Workbook

Sheet Spots
A1: spot_id | B1: spot | C1: zone | D1: ap | E1: dp | F1: sessions | G1: hours | H1: weeks | I1: trash_item | J1: base_trash_hr | K1: trash_per_kill (EDIT) | L1: est_kills_hr | M1: flag
A2: 1 | B2: (OLD) Sycraia (Lower) | C2: balenos | D2: 240 | E2: 330 | F2: 66 | G2: 78.2 | H2: 25 | I2: Underwater Ancient Weapon Power Stone | J2: 4135.6 | L2: =IF(K2="","",J2/K2)
A3: 32 | B3: (OLD) Sycraia (Upper) | C3: balenos | D3: 200 | E3: 260 | F3: 168 | G3: 357.2 | H3: 23 | I3: Destroyed Ancient Weapon Power Stone | J3: 16396 | L3: =IF(K3="","",J3/K3)
A4: 6 | B4: Aakman Temple | C4: valencia | D4: 230 | E4: 300 | F4: 62 | G4: 68 | H4: 28 | I4: Aakman Guardian's Token | J4: 7885.3 | L4: =IF(K4="","",J4/K4)
A5: 11 | B5: Abandoned Monastery | C5: calpheon | D5: 260 | E5: 350 | F5: 10 | G5: 17.5 | H5: 8 | I5: Shadow Knight's Armor Ornament | J5: 4502.8 | L5: =IF(K5="","",J5/K5) | M5: low sample
A6: 183 | B6: Aetherion Castle | C6: edania | D6: 350 | E6: 427 | F6: 24341 | G6: 28593.7 | H6: 53 | I6: Chilled Soul Piece | J6: 5688.5 | L6: =IF(K6="","",J6/K6)
A7: 13 | B7: Altar Imp Habitat | C7: serendia | D7: 220 | E7: 310 | F7: 114 | G7: 144.7 | H7: 35 | I7: Covetous Eye | J7: 5808.8 | L7: =IF(K7="","",J7/K7)
A8: 213 | B8: Aphrodon Temple | C8: edania | D8: 400 | E8: 470 | F8: 20253 | G8: 28606.4 | H8: 5 | I8: Branch of Abundance | J8: 6196.8 | L8: =IF(K8="","",J8/K8)
A9: 216 | B9: Aresion Temple | C9: edania | D9: 415 | E9: 495 | F9: 12087 | G9: 19638 | H9: 5 | I9: Scorched Belt Ornament | J9: 6429.9 | L9: =IF(K9="","",J9/K9)
A10: 27 | B10: Ash Forest | C10: kamasylvia | D10: 300 | E10: 390 | F10: 465 | G10: 548.2 | H10: 48 | I10: Specter's Cloth | J10: 9462.9 | L10: =IF(K10="","",J10/K10)
A11: 84 | B11: Bashim Base | C11: valencia | D11: 100 | E11: 180 | F11: 15 | G11: 13.1 | H11: 9 | I11: Bashim Mane | J11: 5383.6 | L11: =IF(K11="","",J11/K11) | M11: low sample
A12: 89 | B12: Basilisk Den | C12: valencia | D12: 180 | E12: 220 | F12: 9 | G12: 14.7 | H12: 5 | I12: Basilisk Scale | J12: 5668 | L12: =IF(K12="","",J12/K12) | M12: low sample
A13: 12 | B13: Biraghi Den | C13: serendia | D13: 220 | E13: 310 | F13: 129 | G13: 159.1 | H13: 39 | I13: Proof of Reckless Courage | J13: 6695.3 | L13: =IF(K13="","",J13/K13)
A14: 22 | B14: Blood Wolf Settlement | C14: drieghan | D14: 180 | E14: 210 | F14: 306 | G14: 328.7 | H14: 52 | I14: Blood Wolf Mane | J14: 5007.6 | L14: =IF(K14="","",J14/K14)
A15: 18 | B15: Bloody Monastery | C15: serendia | D15: 260 | E15: 340 | F15: 141 | G15: 148.8 | H15: 43 | I15: Proof of Blind Faith | J15: 5865.5 | L15: =IF(K15="","",J15/K15)
A16: 86 | B16: Cadry Ruins | C16: valencia | D16: 140 | E16: 160 | F16: 72 | G16: 92.9 | H16: 34 | I16: Cadry's Token | J16: 4420.8 | L16: =IF(K16="","",J16/K16)
A17: 16 | B17: Castle Ruins | C17: serendia | D17: 230 | E17: 320 | F17: 17 | G17: 29.2 | H17: 10 | I17: Mark of Desperate Rebels | J17: 5069.4 | L17: =IF(K17="","",J17/K17) | M17: low sample
A18: 90 | B18: Centaurus Herd | C18: valencia | D18: 180 | E18: 200 | F18: 54 | G18: 56 | H18: 27 | I18: Centaurus Mane | J18: 5368.2 | L18: =IF(K18="","",J18/K18)
A19: 147 | B19: City of the Dead | C19: ulukita | D19: 320 | E19: 380 | F19: 377 | G19: 449.1 | H19: 18 | I19: Mark of the Black Sands | J19: 9711.6 | L19: =IF(K19="","",J19/K19)
A20: 85 | B20: Crescent Shrine | C20: valencia | D20: 140 | E20: 160 | F20: 5 | G20: 10 | H20: 4 | I20: Token of Crescent | J20: 11172 | L20: =IF(K20="","",J20/K20) | M20: low sample
A21: 8 | B21: Crypt of Resting Thoughts | C21: odyllita | D21: 300 | E21: 400 | F21: 1237 | G21: 1520.7 | H21: 53 | I21: Abyssal Ash | J21: 6186.6 | L21: =IF(K21="","",J21/K21)
A22: 208 | B22: Dark Energy Floodlands (Great Red Sea) | C22: edania | D22: 385 | E22: 450 | F22: 966 | G22: 1123.4 | H22: 30 | I22: Tainted Armor Fragment | J22: 7298.6 | L22: =IF(K22="","",J22/K22)
A23: 209 | B23: Dark Energy Floodlands (Orbita) | C23: edania | D23: 385 | E23: 450 | F23: 1426 | G23: 1635 | H23: 30 | I23: Tainted Armor Fragment | J23: 7405.3 | L23: =IF(K23="","",J23/K23)
A24: 210 | B24: Dark Energy Floodlands (Zephyros) | C24: edania | D24: 385 | E24: 450 | F24: 683 | G24: 848.1 | H24: 27 | I24: Tainted Armor Fragment | J24: 7736.1 | L24: =IF(K24="","",J24/K24)
A25: 153 | B25: Darkseeker's Retreat | C25: ulukita | D25: 340 | E25: 430 | F25: 4671 | G25: 5433.8 | H25: 7 | I25: Decayed Cloth | J25: 9928 | L25: =IF(K25="","",J25/K25)
A26: 82 | B26: Desert Naga Temple | C26: valencia | D26: 100 | E26: 180 | F26: 30 | G26: 37.6 | H26: 15 | I26: Desert Naga's Webfoot | J26: 3735.8 | L26: =IF(K26="","",J26/K26) | M26: low sample
A27: 166 | B27: Dokkebi Forest | C27: morninglight | D27: 335 | E27: 420 | F27: 735 | G27: 939 | H27: 7 | I27: Discarded Kkebicap | J27: 8387.6 | L27: =IF(K27="","",J27/K27)
A28: 218 | B28: Event Horizon | C28: edania | D28: 420 | E28: 505 | F28: 12642 | G28: 22237.8 | H28: 6 | I28: Broken Gloves of the Void | J28: 6451 | L28: =IF(K28="","",J28/K28)
A29: 38 | B29: Fadus Habitat | C29: kamasylvia | D29: 120 | E29: 180 | F29: 42 | G29: 43.6 | H29: 25 | I29: Fadus Armor Fragment | J29: 9456.3 | L29: =IF(K29="","",J29/K29) | M29: low sample
A30: 26 | B30: Forest Ronaros Area | C30: kamasylvia | D30: 240 | E30: 270 | F30: 109 | G30: 105.2 | H30: 40 | I30: Hoof of Forest Ronaros | J30: 5148.5 | L30: =IF(K30="","",J30/K30)
A31: 167 | B31: Fortunate Golden Pig Cave | C31: morninglight | D31: 345 | E31: 438 | F31: 363 | G31: 343.9 | H31: 7 | I31: Shiny Treasure | J31: 8101.5 | L31: =IF(K31="","",J31/K31)
A32: 43 | B32: Gahaz Bandit's Lair | C32: valencia | D32: 140 | E32: 180 | F32: 36 | G32: 35.7 | H32: 18 | I32: Gahaz Seal | J32: 4316.1 | L32: =IF(K32="","",J32/K32) | M32: low sample
A33: 212 | B33: Gavinya Coastal Cliff | C33: valencia | D33: 400 | E33: 470 | F33: 973 | G33: 1201.7 | H33: 5 | I33: Sulfur Golem Fragment | J33: 6222.2 | L33: =IF(K33="","",J33/K33)
A34: 33 | B34: Gyfin Rhasia Temple | C34: kamasylvia | D34: 250 | E34: 320 | F34: 14 | G34: 16.5 | H34: 14 | I34: Fragment of Bronze Artifact | J34: 8901.2 | L34: =IF(K34="","",J34/K34) | M34: low sample
A35: 97 | B35: Gyfin Rhasia Underground | C35: kamasylvia | D35: 290 | E35: 380 | F35: 3515 | G35: 4422.2 | H35: 53 | I35: Bronze Fragment of Delusion | J35: 9964.7 | L35: =IF(K35="","",J35/K35)
A36: 214 | B36: Hermesia Inner Castle | C36: edania | D36: 405 | E36: 485 | F36: 7616 | G36: 10705.5 | H36: 3 | I36: Black Crystal Fragment | J36: 6661 | L36: =IF(K36="","",J36/K36)
A37: 124 | B37: Hexe Sanctuary | C37: calpheon | D37: 300 | E37: 390 | F37: 33871 | G37: 36644.7 | H37: 53 | I37: Howling Bone Fragment | J37: 11493 | L37: =IF(K37="","",J37/K37)
A38: 165 | B38: Honglim Base | C38: morninglight | D38: 270 | E38: 360 | F38: 196 | G38: 215.4 | H38: 7 | I38: Faded Bandit Mask | J38: 11005 | L38: =IF(K38="","",J38/K38)
A39: 3 | B39: Hystria Ruins | C39: valencia | D39: 230 | E39: 300 | F39: 143 | G39: 164.6 | H39: 42 | I39: Hystria Ruins Fragment | J39: 4457.6 | L39: =IF(K39="","",J39/K39)
A40: 110 | B40: Jade Starlight Forest | C40: snowmountain | D40: 270 | E40: 350 | F40: 2201 | G40: 2447.5 | H40: 53 | I40: Starlit Jade Powder | J40: 9588 | L40: =IF(K40="","",J40/K40)
...

Sheet Drops
A1: spot_id | B1: spot | C1: item | D1: base_items_hr | E1: base_trash_hr | F1: per_1000_trash | G1: one_in_n_trash | H1: ci_low_per_1000 | I1: ci_high_per_1000 | J1: est_drops_observed_min | K1: trash_per_kill | L1: chance_per_kill_% | M1: one_in_n_kills | N1: flag
A2: 1 | B2: (OLD) Sycraia (Lower) | C2: Mossy Ancient Ruins Fragment | D2: 144.08 | E2: 4135.6 | F2: 34.838959 | G2: 29 | H2: 34.198453 | I2: 35.488448 | J2: 11262.3 | K2: =IF(IFERROR(INDEX(Spots!$K$2:$K$96,MATCH(A2,Spots!$A$2:$A$96,0)),"")="","",IFERROR(INDEX(Spots!$K$2:$K$96,MATCH(A2,Spots!$A$2:$A$96,0)),"")) | L2: =IF(OR(K2="",F2=""),"",F2/1000*K2*100) | M2: =IF(OR(L2="",L2=0),"",ROUND(100/L2,0))
A3: 1 | B3: (OLD) Sycraia (Lower) | C3: Black Stone | D3: 32.196 | E3: 4135.6 | F3: 7.7850856 | G3: 128 | H3: 7.4838613 | I3: 8.0953237 | J3: 2516.7 | K3: =IF(IFERROR(INDEX(Spots!$K$2:$K$96,MATCH(A3,Spots!$A$2:$A$96,0)),"")="","",IFERROR(INDEX(Spots!$K$2:$K$96,MATCH(A3,Spots!$A$2:$A$96,0)),"")) | L3: =IF(OR(K3="",F3=""),"",F3/1000*K3*100) | M3: =IF(OR(L3="",L3=0),"",ROUND(100/L3,0))
A4: 1 | B4: (OLD) Sycraia (Lower) | C4: Ancient Spirit Dust | D4: 22.205 | E4: 4135.6 | F4: 5.369233 | G4: 186 | H4: 5.1195752 | I4: 5.6279168 | J4: 1735.7 | K4: =IF(IFERROR(INDEX(Spots!$K$2:$K$96,MATCH(A4,Spots!$A$2:$A$96,0)),"")="","",IFERROR(INDEX(Spots!$K$2:$K$96,MATCH(A4,Spots!$A$2:$A$96,0)),"")) | L4: =IF(OR(K4="",F4=""),"",F4/1000*K4*100) | M4: =IF(OR(L4="",L4=0),"",ROUND(100/L4,0))
A5: 1 | B5: (OLD) Sycraia (Lower) | C5: Abyssal Essence | D5: 10.698 | E5: 4135.6 | F5: 2.5868072 | G5: 387 | H5: 2.414423 | I5: 2.7682492 | J5: 836.2 | K5: =IF(IFERROR(INDEX(Spots!$K$2:$K$96,MATCH(A5,Spots!$A$2:$A$96,0)),"")="","",IFERROR(INDEX(Spots!$K$2:$K$96,MATCH(A5,Spots!$A$2:$A$96,0)),"")) | L5: =IF(OR(K5="",F5=""),"",F5/1000*K5*100) | M5: =IF(OR(L5="",L5=0),"",ROUND(100/L5,0))
A6: 1 | B6: (OLD) Sycraia (Lower) | C6: Caphras Stone | D6: 8.556646 | E6: 4135.6 | F6: 2.0690217 | G6: 483 | H6: 1.9151655 | I6: 2.2319477 | J6: 668.8 | K6: =IF(IFERROR(INDEX(Spots!$K$2:$K$96,MATCH(A6,Spots!$A$2:$A$96,0)),"")="","",IFERROR(INDEX(Spots!$K$2:$K$96,MATCH(A6,Spots!$A$2:$A$96,0)),"")) | L6: =IF(OR(K6="",F6=""),"",F6/1000*K6*100) | M6: =IF(OR(L6="",L6=0),"",ROUND(100/L6,0))
A7: 1 | B7: (OLD) Sycraia (Lower) | C7: Sealed Black Magic Crystal | D7: 4.728518 | E7: 4135.6 | F7: 1.1433693 | G7: 875 | H7: 1.0297584 | I7: 1.2660896 | J7: 369.6 | K7: =IF(IFERROR(INDEX(Spots!$K$2:$K$96,MATCH(A7,Spots!$A$2:$A$96,0)),"")="","",IFERROR(INDEX(Spots!$K$2:$K$96,MATCH(A7,Spots!$A$2:$A$96,0)),"")) | L7: =IF(OR(K7="",F7=""),"",F7/1000*K7*100) | M7: =IF(OR(L7="",L7=0),"",ROUND(100/L7,0))
A8: 1 | B8: (OLD) Sycraia (Lower) | C8: Traveler's Map | D8: 0.93055739 | E8: 4135.6 | F8: 0.22501146 | G8: 4444 | H8: 0.17628333 | I8: 0.28303893 | J8: 72.7 | K8: =IF(IFERROR(INDEX(Spots!$K$2:$K$96,MATCH(A8,Spots!$A$2:$A$96,0)),"")="","",IFERROR(INDEX(Spots!$K$2:$K$96,MATCH(A8,Spots!$A$2:$A$96,0)),"")) | L8: =IF(OR(K8="",F8=""),"",F8/1000*K8*100) | M8: =IF(OR(L8="",L8=0),"",ROUND(100/L8,0))
A9: 1 | B9: (OLD) Sycraia (Lower) | C9: Tungrad Ring | D9: 0.30254188 | E9: 4135.6 | F9: 0.073155499 | G9: 13670 | H9: 0.046685947 | I9: 0.10917062 | J9: 23.6 | K9: =IF(IFERROR(INDEX(Spots!$K$2:$K$96,MATCH(A9,Spots!$A$2:$A$96,0)),"")="","",IFERROR(INDEX(Spots!$K$2:$K$96,MATCH(A9,Spots!$A$2:$A$96,0)),"")) | L9: =IF(OR(K9="",F9=""),"",F9/1000*K9*100) | M9: =IF(OR(L9="",L9=0),"",ROUND(100/L9,0)) | N9: low sample
A10: 1 | B10: (OLD) Sycraia (Lower) | C10: Ancient Creature's Scale | D10: 0.2933546 | E10: 4135.6 | F10: 0.070933988 | G10: 14098 | H10: 0.044916658 | I10: 0.10650553 | J10: 22.9 | K10: =IF(IFERROR(INDEX(Spots!$K$2:$K$96,MATCH(A10,Spots!$A$2:$A$96,0)),"")="","",IFERROR(INDEX(Spots!$K$2:$K$96,MATCH(A10,Spots!$A$2:$A$96,0)),"")) | L10: =IF(OR(K10="",F10=""),"",F10/1000*K10*100) | M10: =IF(OR(L10="",L10=0),"",ROUND(100/L10,0)) | N10: low sample
A11: 1 | B11: (OLD) Sycraia (Lower) | C11: Imperfect Lightstone of Earth | D11: 0.29146098 | E11: 4135.6 | F11: 0.070476105 | G11: 14189 | H11: 0.044552863 | I11: 0.10595539 | J11: 22.8 | K11: =IF(IFERROR(INDEX(Spots!$K$2:$K$96,MATCH(A11,Spots!$A$2:$A$96,0)),"")="","",IFERROR(INDEX(Spots!$K$2:$K$96,MATCH(A11,Spots!$A$2:$A$96,0)),"")) | L11: =IF(OR(K11="",F11=""),"",F11/1000*K11*100) | M11: =IF(OR(L11="",L11=0),"",ROUND(100/L11,0)) | N11: low sample
A12: 1 | B12: (OLD) Sycraia (Lower) | C12: Imperfect Lightstone of Fire | D12: 0.11715738 | E12: 4135.6 | F12: 0.028328992 | G12: 35300 | H12: 0.013032829 | I12: 0.053494603 | J12: 9.2 | K12: =IF(IFERROR(INDEX(Spots!$K$2:$K$96,MATCH(A12,Spots!$A$2:$A$96,0)),"")="","",IFERROR(INDEX(Spots!$K$2:$K$96,MATCH(A12,Spots!$A$2:$A$96,0)),"")) | L12: =IF(OR(K12="",F12=""),"",F12/1000*K12*100) | M12: =IF(OR(L12="",L12=0),"",ROUND(100/L12,0)) | N12: low sample
A13: 1 | B13: (OLD) Sycraia (Lower) | C13: Imperfect Lightstone of Wind | D13: 0.04765843 | E13: 4135.6 | F13: 0.011523946 | G13: 86776 | H13: 0.0029046065 | I13: 0.03044255 | J13: 3.7 | K13: =IF(IFERROR(INDEX(Spots!$K$2:$K$96,MATCH(A13,Spots!$A$2:$A$96,0)),"")="","",IFERROR(INDEX(Spots!$K$2:$K$96,MATCH(A13,Spots!$A$2:$A$96,0)),"")) | L13: =IF(OR(K13="",F13=""),"",F13/1000*K13*100) | M13: =IF(OR(L13="",L13=0),"",ROUND(100/L13,0)) | N13: low sample
A14: 1 | B14: (OLD) Sycraia (Lower) | C14: Any Artifact | D14: 0.04344856 | E14: 4135.6 | F14: 0.010505987 | G14: 95184 | H14: 0.0024172646 | I14: 0.028944838 | J14: 3.4 | K14: =IF(IFERROR(INDEX(Spots!$K$2:$K$96,MATCH(A14,Spots!$A$2:$A$96,0)),"")="","",IFERROR(INDEX(Spots!$K$2:$K$96,MATCH(A14,Spots!$A$2:$A$96,0)),"")) | L14: =IF(OR(K14="",F14=""),"",F14/1000*K14*100) | M14: =IF(OR(L14="",L14=0),"",ROUND(100/L14,0)) | N14: low sample
A15: 1 | B15: (OLD) Sycraia (Lower) | C15: Al Yurad's Ring Piece | D15: 0 | E15: 4135.6 | F15: 0 | H15: 0 | I15: 0.011411652 | J15: 0 | K15: =IF(IFERROR(INDEX(Spots!$K$2:$K$96,MATCH(A15,Spots!$A$2:$A$96,0)),"")="","",IFERROR(INDEX(Spots!$K$2:$K$96,MATCH(A15,Spots!$A$2:$A$96,0)),"")) | L15: =IF(OR(K15="",F15=""),"",F15/1000*K15*100) | M15: =IF(OR(L15="",L15=0),"",ROUND(100/L15,0)) | N15: no drops recorded
A16: 32 | B16: (OLD) Sycraia (Upper) | C16: Black Stone | D16: 63.353 | E16: 16396 | F16: 3.8639302 | G16: 259 | H16: 3.8137518 | I16: 3.9146039 | J16: 22632.9 | K16: =IF(IFERROR(INDEX(Spots!$K$2:$K$96,MATCH(A16,Spots!$A$2:$A$96,0)),"")="","",IFERROR(INDEX(Spots!$K$2:$K$96,MATCH(A16,Spots!$A$2:$A$96,0)),"")) | L16: =IF(OR(K16="",F16=""),"",F16/1000*K16*100) | M16: =IF(OR(L16="",L16=0),"",ROUND(100/L16,0))
A17: 32 | B17: (OLD) Sycraia (Upper) | C17: Caphras Stone | D17: 34.13 | E17: 16396 | F17: 2.0816053 | G17: 480 | H17: 2.0448184 | I17: 2.1188878 | J17: 12192.9 | K17: =IF(IFERROR(INDEX(Spots!$K$2:$K$96,MATCH(A17,Spots!$A$2:$A$96,0)),"")="","",IFERROR(INDEX(Spots!$K$2:$K$96,MATCH(A17,Spots!$A$2:$A$96,0)),"")) | L17: =IF(OR(K17="",F17=""),"",F17/1000*K17*100) | M17: =IF(OR(L17="",L17=0),"",ROUND(100/L17,0))
A18: 32 | B18: (OLD) Sycraia (Upper) | C18: Ancient Spirit Dust | D18: 30.237 | E18: 16396 | F18: 1.8441693 | G18: 542 | H18: 1.8095535 | I18: 1.8792808 | J18: 10802.2 | K18: =IF(IFERROR(INDEX(Spots!$K$2:$K$96,MATCH(A18,Spots!$A$2:$A$96,0)),"")="","",IFERROR(INDEX(Spots!$K$2:$K$96,MATCH(A18,Spots!$A$2:$A$96,0)),"")) | L18: =IF(OR(K18="",F18=""),"",F18/1000*K18*100) | M18: =IF(OR(L18="",L18=0),"",ROUND(100/L18,0))
A19: 32 | B19: (OLD) Sycraia (Upper) | C19: Abyssal Essence | D19: 19.233 | E19: 16396 | F19: 1.17303 | G19: 852 | H19: 1.1454553 | I19: 1.2011009 | J19: 6871 | K19: =IF(IFERROR(INDEX(Spots!$K$2:$K$96,MATCH(A19,Spots!$A$2:$A$96,0)),"")="","",IFERROR(INDEX(Spots!$K$2:$K$96,MATCH(A19,Spots!$A$2:$A$96,0)),"")) | L19: =IF(OR(K19="",F19=""),"",F19/1000*K19*100) | M19: =IF(OR(L19="",L19=0),"",ROUND(100/L19,0))
A20: 32 | B20: (OLD) Sycraia (Upper) | C20: Fragment of the Deep Sea | D20: 15.006 | E20: 16396 | F20: 0.91522323 | G20: 1093 | H20: 0.89088538 | I20: 0.94005748 | J20: 5360.9 | K20: =IF(IFERROR(INDEX(Spots!$K$2:$K$96,MATCH(A20,Spots!$A$2:$A$96,0)),"")="","",IFERROR(INDEX(Spots!$K$2:$K$96,MATCH(A20,Spots!$A$2:$A$96,0)),"")) | L20: =IF(OR(K20="",F20=""),"",F20/1000*K20*100) | M20: =IF(OR(L20="",L20=0),"",ROUND(100/L20,0))
A21: 32 | B21: (OLD) Sycraia (Upper) | C21: Mass of Pure Magic | D21: 3.720084 | E21: 16396 | F21: 0.22688973 | G21: 4407 | H21: 0.2148536 | I21: 0.23942456 | J21: 1329 | K21: =IF(IFERROR(INDEX(Spots!$K$2:$K$96,MATCH(A21,Spots!$A$2:$A$96,0)),"")="","",IFERROR(INDEX(Spots!$K$2:$K$96,MATCH(A21,Spots!$A$2:$A$96,0)),"")) | L21: =IF(OR(K21="",F21=""),"",F21/1000*K21*100) | M21: =IF(OR(L21="",L21=0),"",ROUND(100/L21,0))
A22: 32 | B22: (OLD) Sycraia (Upper) | C22: Sealed Black Magic Crystal | D22: 3.456963 | E22: 16396 | F22: 0.21084185 | G22: 4743 | H22: 0.19924506 | I22: 0.22293751 | J22: 1235 | K22: =IF(IFERROR(INDEX(Spots!$K$2:$K$96,MATCH(A22,Spots!$A$2:$A$96,0)),"")="","",IFERROR(INDEX(Spots!$K$2:$K$96,MATCH(A22,Spots!$A$2:$A$96,0)),"")) | L22: =IF(OR(K22="",F22=""),"",F22/1000*K22*100) | M22: =IF(OR(L22="",L22=0),"",ROUND(100/L22,0))
A23: 32 | B23: (OLD) Sycraia (Upper) | C23: Any Artifact | D23: 0.73617915 | E23: 16396 | F23: 0.044899924 | G23: 22272 | H23: 0.039636662 | I23: 0.050667497 | J23: 263 | K23: =IF(IFERROR(INDEX(Spots!$K$2:$K$96,MATCH(A23,Spots!$A$2:$A$96,0)),"")="","",IFERROR(INDEX(Spots!$K$2:$K$96,MATCH(A23,Spots!$A$2:$A$96,0)),"")) | L23: =IF(OR(K23="",F23=""),"",F23/1000*K23*100) | M23: =IF(OR(L23="",L23=0),"",ROUND(100/L23,0))
A24: 32 | B24: (OLD) Sycraia (Upper) | C24: Ancient Creature's Scale | D24: 0.53743877 | E24: 16396 | F24: 0.032778652 | G24: 30508 | H24: 0.028305628 | I24: 0.03775769 | J24: 192 | K24: =IF(IFERROR(INDEX(Spots!$K$2:$K$96,MATCH(A24,Spots!$A$2:$A$96,0)),"")="","",IFERROR(INDEX(Spots!$K$2:$K$96,MATCH(A24,Spots!$A$2:$A$96,0)),"")) | L24: =IF(OR(K24="",F24=""),"",F24/1000*K24*100) | M24: =IF(OR(L24="",L24=0),"",ROUND(100/L24,0))
A25: 32 | B25: (OLD) Sycraia (Upper) | C25: Imperfect Lightstone of Wind | D25: 0.53463961 | E25: 16396 | F25: 0.032607929 | G25: 30667 | H25: 0.028147 | I25: 0.037574904 | J25: 191 | K25: =IF(IFERROR(INDEX(Spots!$K$2:$K$96,MATCH(A25,Spots!$A$2:$A$96,0)),"")="","",IFERROR(INDEX(Spots!$K$2:$K$96,MATCH(A25,Spots!$A$2:$A$96,0)),"")) | L25: =IF(OR(K25="",F25=""),"",F25/1000*K25*100) | M25: =IF(OR(L25="",L25=0),"",ROUND(100/L25,0))
A26: 32 | B26: (OLD) Sycraia (Upper) | C26: Tungrad Ring | D26: 0.51784465 | E26: 16396 | F26: 0.031583597 | G26: 31662 | H26: 0.027195911 | I26: 0.036477516 | J26: 185 | K26: =IF(IFERROR(INDEX(Spots!$K$2:$K$96,MATCH(A26,Spots!$A$2:$A$96,0)),"")="","",IFERROR(INDEX(Spots!$K$2:$K$96,MATCH(A26,Spots!$A$2:$A$96,0)),"")) | L26: =IF(OR(K26="",F26=""),"",F26/1000*K26*100) | M26: =IF(OR(L26="",L26=0),"",ROUND(100/L26,0))
A27: 32 | B27: (OLD) Sycraia (Upper) | C27: Specter's Energy | D27: 0.34429671 | E27: 16396 | F27: 0.020998823 | G27: 47622 | H27: 0.01745173 | I27: 0.025054829 | J27: 123 | K27: =IF(IFERROR(INDEX(Spots!$K$2:$K$96,MATCH(A27,Spots!$A$2:$A$96,0)),"")="","",IFERROR(INDEX(Spots!$K$2:$K$96,MATCH(A27,Spots!$A$2:$A$96,0)),"")) | L27: =IF(OR(K27="",F27=""),"",F27/1000*K27*100) | M27: =IF(OR(L27="",L27=0),"",ROUND(100/L27,0))
... A29: 32 | B29: (OLD) Sycraia (Upper) | C29: Imperfect Lightstone of Earth | D29: 0.10076977 | E29: 16396 | F29: 0.0061459972 | G29: 162708 | H29: 0.0043039526 | I29: 0.0085089484 | J29: 36 | K29: =IF(IFERROR(INDEX(Spots!$K$2:$K$96,MATCH(A29,Spots!$A$2:$A$96,0)),"")="","",IFERROR(INDEX(Spots!$K$2:$K$96,MATCH(A29,Spots!$A$2:$A$96,0)),"")) | L29: =IF(OR(K29="",F29=""),"",F29/1000*K29*100) | M29: =IF(OR(L29="",L29=0),"",ROUND(100/L29,0))
A30: 32 | B30: (OLD) Sycraia (Upper) | C30: Imperfect Lightstone of Fire | D30: 0.07837649 | E30: 16396 | F30: 0.0047802202 | G30: 209195 | H30: 0.0031756952 | I30: 0.0069090488 | J30: 28 | K30: =IF(IFERROR(INDEX(Spots!$K$2:$K$96,MATCH(A30,Spots!$A$2:$A$96,0)),"")="","",IFERROR(INDEX(Spots!$K$2:$K$96,MATCH(A30,Spots!$A$2:$A$96,0)),"")) | L30: =IF(OR(K30="",F30=""),"",F30/1000*K30*100) | M30: =IF(OR(L30="",L30=0),"",ROUND(100/L30,0)) | N30: low sample
A31: 32 | B31: (OLD) Sycraia (Upper) | C31: Al Yurad's Ring Piece | D31: 0.01679496 | E31: 16396 | F31: 0.0010243328 | G31: 976245 | H31: 0.00037404204 | I31: 0.0022296132 | J31: 6 | K31: =IF(IFERROR(INDEX(Spots!$K$2:$K$96,MATCH(A31,Spots!$A$2:$A$96,0)),"")="","",IFERROR(INDEX(Spots!$K$2:$K$96,MATCH(A31,Spots!$A$2:$A$96,0)),"")) | L31: =IF(OR(K31="",F31=""),"",F31/1000*K31*100) | M31: =IF(OR(L31="",L31=0),"",ROUND(100/L31,0)) | N31: low sample
A32: 32 | B32: (OLD) Sycraia (Upper) | C32: Great Marni's Stone (Sycraia Upper Zone) | D32: 0.00279916 | E32: 16396 | F32: 0.00017072213 | G32: 5857472 | H32: 2.23136e-06 | I32: 0.00094987345 | J32: 1 | K32: =IF(IFERROR(INDEX(Spots!$K$2:$K$96,MATCH(A32,Spots!$A$2:$A$96,0)),"")="","",IFERROR(INDEX(Spots!$K$2:$K$96,MATCH(A32,Spots!$A$2:$A$96,0)),"")) | L32: =IF(OR(K32="",F32=""),"",F32/1000*K32*100) | M32: =IF(OR(L32="",L32=0),"",ROUND(100/L32,0)) | N32: low sample
A33: 6 | B33: Aakman Temple | C33: Black Stone | D33: 34.338 | E33: 7885.3 | F33: 4.3546853 | G33: 230 | H33: 4.1798252 | I33: 4.5349811 | J33: 2335 | K33: =IF(IFERROR(INDEX(Spots!$K$2:$K$96,MATCH(A33,Spots!$A$2:$A$96,0)),"")="","",IFERROR(INDEX(Spots!$K$2:$K$96,MATCH(A33,Spots!$A$2:$A$96,0)),"")) | L33: =IF(OR(K33="",F33=""),"",F33/1000*K33*100) | M33: =IF(OR(L33="",L33=0),"",ROUND(100/L33,0))
A34: 6 | B34: Aakman Temple | C34: Caphras Stone | D34: 11.261 | E34: 7885.3 | F34: 1.4281004 | G34: 700 | H34: 1.3287258 | I34: 1.5329385 | J34: 765.7 | K34: =IF(IFERROR(INDEX(Spots!$K$2:$K$96,MATCH(A34,Spots!$A$2:$A$96,0)),"")="","",IFERROR(INDEX(Spots!$K$2:$K$96,MATCH(A34,Spots!$A$2:$A$96,0)),"")) | L34: =IF(OR(K34="",F34=""),"",F34/1000*K34*100) | M34: =IF(OR(L34="",L34=0),"",ROUND(100/L34,0))
A35: 6 | B35: Aakman Temple | C35: Scroll Written in Ancient Language | D35: 10.395 | E35: 7885.3 | F35: 1.3182758 | G35: 759 | H35: 1.2228688 | I35: 1.4191489 | J35: 706.9 | K35: =IF(IFERROR(INDEX(Spots!$K$2:$K$96,MATCH(A35,Spots!$A$2:$A$96,0)),"")="","",IFERROR(INDEX(Spots!$K$2:$K$96,MATCH(A35,Spots!$A$2:$A$96,0)),"")) | L35: =IF(OR(K35="",F35=""),"",F35/1000*K35*100) | M35: =IF(OR(L35="",L35=0),"",ROUND(100/L35,0))
A36: 6 | B36: Aakman Temple | C36: Sealed Black Magic Crystal | D36: 2.845403 | E36: 7885.3 | F36: 0.36084905 | G36: 2771 | H36: 0.3117897 | I36: 0.41543563 | J36: 193.5 | K36: =IF(IFERROR(INDEX(Spots!$K$2:$K$96,MATCH(A36,Spots!$A$2:$A$96,0)),"")="","",IFERROR(INDEX(Spots!$K$2:$K$96,MATCH(A36,Spots!$A$2:$A$96,0)),"")) | L36: =IF(OR(K36="",F36=""),"",F36/1000*K36*100) | M36: =IF(OR(L36="",L36=0),"",ROUND(100/L36,0))
A37: 6 | B37: Aakman Temple | C37: Ancient Spirit Dust | D37: 2.389619 | E37: 7885.3 | F37: 0.30304732 | G37: 3300 | H37: 0.25823961 | I37: 0.35339382 | J37: 162.5 | K37: =IF(IFERROR(INDEX(Spots!$K$2:$K$96,MATCH(A37,Spots!$A$2:$A$96,0)),"")="","",IFERROR(INDEX(Spots!$K$2:$K$96,MATCH(A37,Spots!$A$2:$A$96,0)),"")) | L37: =IF(OR(K37="",F37=""),"",F37/1000*K37*100) | M37: =IF(OR(L37="",L37=0),"",ROUND(100/L37,0))
A38: 6 | B38: Aakman Temple | C38: Mass of Pure Magic | D38: 1.169322 | E38: 7885.3 | F38: 0.14829138 | G38: 6743 | H38: 0.11749316 | I38: 0.1846872 | J38: 79.5 | K38: =IF(IFERROR(INDEX(Spots!$K$2:$K$96,MATCH(A38,Spots!$A$2:$A$96,0)),"")="","",IFERROR(INDEX(Spots!$K$2:$K$96,MATCH(A38,Spots!$A$2:$A$96,0)),"")) | L38: =IF(OR(K38="",F38=""),"",F38/1000*K38*100) | M38: =IF(OR(L38="",L38=0),"",ROUND(100/L38,0))
A39: 6 | B39: Aakman Temple | C39: Traveler's Map | D39: 0.62038535 | E39: 7885.3 | F39: 0.078676189 | G39: 12710 | H39: 0.056741035 | I39: 0.10628039 | J39: 42.2 | K39: =IF(IFERROR(INDEX(Spots!$K$2:$K$96,MATCH(A39,Spots!$A$2:$A$96,0)),"")="","",IFERROR(INDEX(Spots!$K$2:$K$96,MATCH(A39,Spots!$A$2:$A$96,0)),"")) | L39: =IF(OR(K39="",F39=""),"",F39/1000*K39*100) | M39: =IF(OR(L39="",L39=0),"",ROUND(100/L39,0))
A40: 6 | B40: Aakman Temple | C40: Part for Explorer's Compass | D40: 0.59296793 | E40: 7885.3 | F40: 0.075199159 | G40: 13298 | H40: 0.05379536 | I40: 0.10227794 | J40: 40.3 | K40: =IF(IFERROR(INDEX(Spots!$K$2:$K$96,MATCH(A40,Spots!$A$2:$A$96,0)),"")="","",IFERROR(INDEX(Spots!$K$2:$K$96,MATCH(A40,Spots!$A$2:$A$96,0)),"")) | L40: =IF(OR(K40="",F40=""),"",F40/1000*K40*100) | M40: =IF(OR(L40="",L40=0),"",ROUND(100/L40,0))
A41: 6 | B41: Aakman Temple | C41: Imperfect Lightstone of Fire | D41: 0.45559253 | E41: 7885.3 | F41: 0.05777745 | G41: 17308 | H41: 0.039244198 | I41: 0.082022778 | J41: 31 | K41: =IF(IFERROR(INDEX(Spots!$K$2:$K$96,MATCH(A41,Spots!$A$2:$A$96,0)),"")="","",IFERROR(INDEX(Spots!$K$2:$K$96,MATCH(A41,Spots!$A$2:$A$96,0)),"")) | L41: =IF(OR(K41="",F41=""),"",F41/1000*K41*100) | M41: =IF(OR(L41="",L41=0),"",ROUND(100/L41,0))
...

Sheet Notes
A1: Source: Garmoth collective grind data, 2025-10-09 to 2026-10-15.
A2: All rates are base: 0% item drop rate, no loot scroll / Agris (Garmoth normalizes before storing).
A3: per_1000_trash = item hourly_rate / trash hourly_rate * 1000. Independent of clear speed and buffs.
A4: Trash per kill varies by spot, so per-kill chance needs Spots!K (yellow). Fill it in; Drops sheet updates.
A5: chance_per_kill_% = per_1000_trash / 1000 * trash_per_kill * 100. With Item Drop Rate buff, multiply by (1 + DR%).
A6: Items that drop in stacks: values are expected items, not drop events.
A7: CI: 95% Poisson interval on estimated observed drops (base rate * hours). Real samples are larger (sessions were buffed), so intervals are conservative.
A8: Flags: 'low sample' = spot under 50h or fewer than 30 estimated drops; 'no drops recorded' = rate 0, ci_high gives an upper bound.
